Workbook

Sheet 实物作品
A1: 电子系统课程设计 实物作品评分表
A3: 设计题目 | C3: 数控直流电源 | H3: 测评教师 | I3: 马庆龙
A4: 学生信息
A5: 组号（示例：息1-1） | C5: 息2-8
A6: 成员1 | B6: 姓名 | C6: 黄元泽 | D6: 学号 | E6: 23211319 | F6: 班级 | G6: 信息2302 | H6: 选课教师 | I6: 马庆龙
A7: 成员2 | B7: 姓名 | C7: 廖一可 | D7: 学号 | E7: 23211326 | F7: 班级 | G7: 信息2302 | H7: 选课教师 | I7: 马庆龙
A8: 成员3 | B8: 姓名 | C8: 崔以恒 | D8: 学号 | E8: 23211288 | F8: 班级 | G8: 信息2301 | H8: 选课教师 | I8: 马庆龙
A9: 备注 | E9: 提交批次 | G9: 实物作品原始总分 | I9: =IF(AND(D20="否",I20="否",I21="是",I22="是",B22="信息正确",G22="单路",ROUND(I22,0)>=5,ROUND(I22,0)<=7),SUM(I25,I69,I91,I110),0) -> #VALUE!
A10: 测评须知 | B10: 1.提前10分钟到现场进行准备，准备过程中可以使用仪器对被测电路进行调试，可以使用电烙铁焊接电路，允许更换损坏的元器件（不含单片机等可编程器件），但不允许重新下载单片机程序，不允许私自更换已提交的作品（如有违反按考试违纪处理），未经测评教师允许不得使用计算机。
B12: 2.测评开始前做好所有调试准备工作。测评正式开始后禁止更改电路连线，除设计任务中特别说明外禁止调整元件（含电位器等参数可调元件）的参数，禁止使用示波器等仪器对电路进行调试，除单片机死机外禁止对单片机进行复位，禁止重新下载程序，否则之前的测试结果无效，须全部重测，每组最多只允许重测1次。
B14: 3.测评开始前应在作品上清楚标注所有按键、指示灯及接口的名称。
B15: 4.提交的电路原理图必须与实际电路完全一致，否则不予测试，如有差异允许现场修改电路图。
B16: 5.作品全程连接“测试用负载电路”（包含滑动变阻器、电压表和电流表，以下简称“负载”）进行测试。
B17: 6.整个作品中只能有一个电压调整旋钮和一个电流调整旋钮，即在基本部分测试和提高部分测试中必须使用相同的调节输出电压和最大输出电流的旋钮。
A19: 测前检查
A20: 作品中违规使用成品电路模块 | D20: 否 | E20: 作品中使用除MC34063以外的开关电源芯片 | I20: 否
A21: 使用MC34063芯片数量 | C21: 2 | D21: 单片机型号 | E21: STM32 | G21: 单片机最小系统板合规 | I21: 是
A22: 开机画面 | B22: 信息正确 | C22: 电源结构 | D22: 开关升压-开关降压 | F22: 供电通道数 | G22: 单路 | H22: 供电电压 | I22: 5.0V
A23: 备注
A24: 测试记录
A25: 1. 基本部分（60分） | G25: 基本部分总分 | I25: =SUM(I26,I38,I48,I53) -> 60
A26: （1）稳压输出（CV）功能（20分） | H26: 本项总分 | I26: =SUM(I32:I36,B37) -> 20
A27: 测试方法 | B27: 1.将负载滑动变阻器调整至200Ω，通过观察电压表示数设置作品输出电压为1.5V，最大输出电流为0.4A（或0-0.4A范围内可达到的最大输出电流），调整负载滑动变阻器逐渐减小阻值，直至作品进入恒流输出状态，观察并记录在整个恒压输出状态中作品输出电压随负载电阻变化情况。如果作品无恒流功能，则在测试过程中作品最大输出电流不超过0.4A。 2.分别设置作品输出电压为4.0V、5.0V以及1.5V-5.0V之间任一随机电压，重复以上测试过程。 3.在以上测试过程中，全程使用示波器观察并记录负载两端电压纹波的最大值（只算纹波，不算毛刺）。 4.观察并记录作品处于稳压输出状态时“CV”指示灯是否正常点亮。
A32: 测试记录 | B32: 目标输出电压 | D32: 1.5 | E32: 4 | F32: 5 | G32: 3.8 | H32: 得分 | I32: =((IF(ROUND(D33,1)=D32,2,0)+IF(D34<=0.1,1,0)*IF(ROUND(D33,1)=D32,1,0)*NOT(ISBLANK(D34)))+(IF(ROUND(E33,1)=E32,2,0)+IF(E34<=0.1,1,0)*IF(ROUND(E33,1)=E32,1,0)*NOT(ISBLANK(E34)))+(IF(ROUND(F33,1)=F32,2,0)+IF(F34<=0.1,1,0)*IF(ROUND(F33,1)=F32,1,0)*NOT(ISBLANK(F34)))+(IF(ROUND(G33,1)=G32,2,0)+IF(G34<=0.1,1,0)*IF(ROUND(G33,1)=G32,1,0)*NOT(ISBLANK(G34))))*IF(OR(D35="连续可调",D35="步进调整"),1,0) -> 12
B33: 实际输出电压(@200Ω) | D33: 1.47 | E33: 3.98 | F33: 4.99 | G33: 3.77
B34: 输出电压随负载变化量 | D34: 0.02 | E34: 0.02 | F34: 0.02 | G34: 0.02
B35: 电压调整方式 | D35: 步进调整 | E35: 输出电压纹波(峰峰值) | G35: 0.042 | H35: 得分 | I35: =IF(G35<=0.05,5,IF(G35<=0.1,2,0))*NOT(ISBLANK(G35)) -> 5
B36: 稳压输出时CV指示灯 | D36: 点亮 | E36: 非稳压输出时CV指示灯 | G36: 熄灭 | H36: 得分 | I36: =IF(AND(D36="点亮",G36="熄灭")=TRUE,3,0) -> 3
A37: 分数调整 | C37: 备注 | D37: 高电压时纹波较小，小于0.05，符合要求；低电压时100mV
A38: （2）恒流输出（CC）功能（20分） | H38: 本项总分 | I38: =SUM(I43:I46,B47) -> 20
A39: 测试方法 | B39: 1.设置作品输出电压为5V（或1.5-5V范围内最大输出电压），先将负载滑动变阻器调整至200Ω，再逐渐减小其电阻值使作品进入恒流输出模式，对照负载电流表设置作品最大输出电流为0.10A，观察并记录负载电流表的读数，在保证负载两端电压不低于1.5V的前提下，继续调整负载滑动变阻器的电阻值，观察并记录在恒流输出状态下负载上的电流随负载滑动变阻器电阻值变化情况。 2.分别设置作品输出电流为0.20A、0.30A、0.40A，重复以上测试过程。 3.观察并记录作品处于恒流输出状态时“CC”指示灯是否正常点亮。
A43: 测试记录 | B43: 设置最大输出电流 | D43: 0.1 | E43: 0.2 | F43: 0.3 | G43: 0.4 | H43: 得分 | I43: =(IF(ROUND(D44,2)=D43,1,0)+IF(D45<=0.01,2.5,0)*IF(ROUND(D44,2)=D43,1,0)*NOT(ISBLANK(D45)))+(IF(ROUND(E44,2)=E43,2,0)+IF(E45<=0.01,2.5,0)*IF(ROUND(E44,2)=E43,1,0)*NOT(ISBLANK(E45)))+(IF(ROUND(F44,2)=F43,2,0)+IF(F45<=0.01,2.5,0)*IF(ROUND(F44,2)=F43,1,0)*NOT(ISBLANK(F45)))+(IF(ROUND(G44,2)=G43,2,0)+IF(G45<=0.01,2.5,0)*IF(ROUND(G44,2)=G43,1,0)*NOT(ISBLANK(G45))) -> 17
B44: 实际最大输出电流 | D44: 0.098 | E44: 0.198 | F44: 0.299 | G44: 0.399
B45: 输出电流随负载变化量 | D45: 0.001 | E45: 0.001 | F45: 0.002 | G45: 0.002
B46: 恒流输出时CC指示灯 | D46: 点亮 | E46: 非恒流输出时CC指示灯 | G46: 熄灭 | H46: 得分 | I46: =IF(AND(D46="点亮",G46="熄灭")=TRUE,3,0) -> 3
A47: 分数调整 | C47: 备注
A48: （3）供电输出开关及状态指示（5分） | H48: 本项总分 | I48: =SUM(I51,B52) -> 5
A49: 测试方法 | B49: 按下“输出控制开关”（注意该按键必须为无锁按键或矩阵键盘中的按键，否则不予测试），通过负载电压表和电流表观察作品实际输出变化情况和“输出状态指示灯”显示情况。
A51: 测试记录 | B51: 输出控制开关 | D51: 工作正常 | E51: 输出状态指示灯 | G51: 工作正常 | H51: 得分 | I51: =IF(D51="工作正常",1,IF(D51="不稳定",0.5,0))*3+IF(G51="工作正常",1,IF(G51="不稳定",0.5,0))*2 -> 5
A52: 分数调整 | C52: 备注
...

Sheet 设计报告
A1: 电子系统课程设计 设计报告评分表
A3: 设计题目 | C3: =实物作品!C3 -> 数控直流电源 | H3: 评阅教师
A4: 学生信息
A5: 组号 | C5: =实物作品!C5 -> 息2-8
A6: 成员1 | B6: 姓名 | C6: =实物作品!C6 -> 黄元泽 | D6: 学号 | E6: =实物作品!E6 -> 23211319 | F6: 班级 | G6: =实物作品!G6 -> 信息2302 | H6: 任课教师 | I6: =实物作品!I6 -> 马庆龙
A7: 成员2 | B7: 姓名 | C7: =实物作品!C7 -> 廖一可 | D7: 学号 | E7: =实物作品!E7 -> 23211326 | F7: 班级 | G7: =实物作品!G7 -> 信息2302 | H7: 任课教师 | I7: =实物作品!I7 -> 马庆龙
A8: 成员3 | B8: 姓名 | C8: =实物作品!C8 -> 崔以恒 | D8: 学号 | E8: =实物作品!E8 -> 23211288 | F8: 班级 | G8: =实物作品!G8 -> 信息2301 | H8: 任课教师 | I8: =实物作品!I8 -> 马庆龙
A9: 备注 | G9: 设计报告原始总分 | I9: =SUM(E13,E17,E20,E23,E26,E29,E34) -> 0
A10: 设计报告评阅
A11: 报告内容 | E11: 评分 | F11: 备注
A12: 1 设计任务要求 | E12: ——
A13: 2 设计方案及论证（30分） | E13: =SUM(E14:E16) -> 0
A14: 2.1 总体方案设计（10分）
A15: 2.2 具体电路设计（10分）
A16: 2.3 嵌入式软件设计（10分） | F16: 未编写嵌入式软件的本项成绩折算进2.2。
A17: 3 制作与调试过程（20分） | E17: =SUM(E18:E19) -> 0
A18: 3.1 制作与调试流程（10分）
A19: 3.2 遇到的问题与解决方法（10分）
A20: 4 系统测试（10分） | E20: =SUM(E21:E22) -> 0
A21: 4.1 测试方法与测试数据（5分）
A22: 4.2 数据分析与结论（5分）
A23: 5 系统使用说明（10分） | E23: =SUM(E24:E25) -> 0
A24: 5.1 功能与外观（5分）
A25: 5.2 操作使用方法（5分）
A26: 6 成本管理（10分） | E26: =SUM(E27:E28) -> 0
A27: 6.1 成本控制与核算（5分）
A28: 6.2 成本控制效果评价（5分）
A29: 7 总结（10分） | E29: =SUM(E30:E31) -> 0
A30: 7.1 人员分工与协作（5分）
A31: 7.2 个人收获与体会（5分）
A32: 7.3 对本课程的意见与建议 | E32: ——
A33: 8 参考文献 | E33: ——
A34: 书写规范（10分）
A35: 备注

Sheet 面试答辩
A1: 电子系统课程设计 面试答辩评分表
A3: 设计题目 | C3: =实物作品!C3 -> 数控直流电源 | H3: 面试教师
A4: 组号 | C4: =实物作品!C5 -> 息2-8
A5: 成员1 答辩情况 | B5: 姓名 | C5: =实物作品!C6 -> 黄元泽 | D5: 学号 | E5: =实物作品!E6 -> 23211319 | F5: 班级 | G5: =实物作品!G6 -> 信息2302 | H5: 任课教师 | I5: =实物作品!I6 -> 马庆龙
B6: 分工
B7: 独立完成 | D7: 小组贡献 （30分） | F7: 工作质量 （30分） | H7: 答辩成绩 | I7: =IF(OR(C7="N",E7<10,E9<10),0,SUM(E7,G7,E9,G9)) -> 0
D9: 原理理解 （30分） | F9: 口头表达 （10分）
B11: 备注
A15: 成员2 答辩情况 | B15: 姓名 | C15: =实物作品!C7 -> 廖一可 | D15: 学号 | E15: =实物作品!E7 -> 23211326 | F15: 班级 | G15: =实物作品!G7 -> 信息2302 | H15: 任课教师 | I15: =实物作品!I7 -> 马庆龙
B16: 分工
B17: 独立完成 | D17: 小组贡献 （30分） | F17: 工作质量 （30分） | H17: 答辩成绩 | I17: =IF(OR(C17="N",E17<10,E19<10),0,SUM(E17,G17,E19,G19)) -> 0
D19: 原理理解 （30分） | F19: 口头表达 （10分）
B21: 备注
A25: 成员3 答辩情况 | B25: 姓名 | C25: =实物作品!C8 -> 崔以恒 | D25: 学号 | E25: =实物作品!E8 -> 23211288 | F25: 班级 | G25: =实物作品!G8 -> 信息2301 | H25: 任课教师 | I25: =实物作品!I8 -> 马庆龙
B26: 分工
B27: 独立完成 | D27: 小组贡献 （30分） | F27: 工作质量 （30分） | H27: 答辩成绩 | I27: =IF(OR(C27="N",E27<10,E29<10),0,SUM(E27,G27,E29,G29)) -> 0
D29: 原理理解 （30分） | F29: 口头表达 （10分）
B31: 备注
A35: 备注

Sheet 总表登分
A1: 序号 | B1: 学号 | C1: 姓名 | D1: 班级 | E1: 选课教师 | F1: 组号 | G1: 提交批次 | H1: 分工 | I1: 作品完成 （满分100分） | J1: 独立完成 （是/否） | K1: 小组贡献 （30分） | L1: 工作质量 （30分） | M1: 原理理解 （30分） | N1: 口头表达 （10分） | O1: 面试答辩 （满分100分） | P1: 答辩成绩调整系数 | Q1: 设计方案及论证 （30分） | R1: 制作及调试过程 （20分） | S1: 系统测试 （10分） | T1: 使用说明书 （10分） | U1: 成本管理 （10分） | V1: 总结 （10分） | W1: 书写规范 （10分） | X1: 设计报告成绩 （满分100分） | Y1: 报告成绩调整系数
I2: A | J2: B1 | K2: B2 | L2: B3 | M2: B4 | N2: B5 | O2: B | Q2: C1 | R2: C2 | S2: C3 | T2: C4 | U2: C5 | V2: C6 | W2: C7 | X2: C
A3: 1 | B3: =实物作品!E6 -> 23211319 | C3: =实物作品!C6 -> 黄元泽 | D3: =实物作品!G6 -> 信息2302 | E3: =实物作品!I6 -> 马庆龙 | F3: =实物作品!C5 -> 息2-8 | G3: =实物作品!F9 -> 0 | H3: =面试答辩!C6 -> 0 | I3: =实物作品!I9 -> #VALUE! | J3: =面试答辩!C7 -> 0 | K3: =面试答辩!E7 -> 0 | L3: =面试答辩!G7 -> 0 | M3: =面试答辩!E9 -> 0 | N3: =面试答辩!G9 -> 0 | O3: =面试答辩!I7 -> 0 | P3: 1 | Q3: =设计报告!E13 -> 0 | R3: =设计报告!E17 -> 0 | S3: =设计报告!E20 -> 0 | T3: =设计报告!E23 -> 0 | U3: =设计报告!E26 -> 0 | V3: =设计报告!E29 -> 0 | W3: =设计报告!E34 -> 0 | X3: =设计报告!I9 -> 0 | Y3: 1
A4: 2 | B4: =实物作品!E7 -> 23211326 | C4: =实物作品!C7 -> 廖一可 | D4: =实物作品!G7 -> 信息2302 | E4: =实物作品!I7 -> 马庆龙 | F4: =实物作品!C5 -> 息2-8 | G4: =实物作品!F9 -> 0 | H4: =面试答辩!C16 -> 0 | I4: =实物作品!I9 -> #VALUE! | J4: =面试答辩!C17 -> 0 | K4: =面试答辩!E17 -> 0 | L4: =面试答辩!G17 -> 0 | M4: =面试答辩!E19 -> 0 | N4: =面试答辩!G19 -> 0 | O4: =面试答辩!I17 -> 0 | P4: 1 | Q4: =设计报告!E13 -> 0 | R4: =设计报告!E17 -> 0 | S4: =设计报告!E20 -> 0 | T4: =设计报告!E23 -> 0 | U4: =设计报告!E26 -> 0 | V4: =设计报告!E29 -> 0 | W4: =设计报告!E34 -> 0 | X4: =设计报告!I9 -> 0 | Y4: 1
A5: 3 | B5: =实物作品!E8 -> 23211288 | C5: =实物作品!C8 -> 崔以恒 | D5: =实物作品!G8 -> 信息2301 | E5: =实物作品!I8 -> 马庆龙 | F5: =实物作品!C5 -> 息2-8 | G5: =实物作品!F9 -> 0 | H5: =面试答辩!C26 -> 0 | I5: =实物作品!I9 -> #VALUE! | J5: =面试答辩!C27 -> 0 | K5: =面试答辩!E27 -> 0 | L5: =面试答辩!G27 -> 0 | M5: =面试答辩!E29 -> 0 | N5: =面试答辩!G29 -> 0 | O5: =面试答辩!I27 -> 0 | P5: 1 | Q5: =设计报告!E13 -> 0 | R5: =设计报告!E17 -> 0 | S5: =设计报告!E20 -> 0 | T5: =设计报告!E23 -> 0 | U5: =设计报告!E26 -> 0 | V5: =设计报告!E29 -> 0 | W5: =设计报告!E34 -> 0 | X5: =设计报告!I9 -> 0 | Y5: 1
